<?xml version="1.0" ?>
<!-- =================================================================================== -->
<!-- |    This document was autogenerated by xacro from /home/hzw/RosFunctionExtension/ws_robot_arm/src/model/xacro/model/my_arm.xacro | -->
<!-- |    EDITING THIS FILE BY HAND IS NOT RECOMMENDED                                 | -->
<!-- =================================================================================== -->
<robot name="arm_dyn">
    <!-- Fixed block -->
    <link name="fixed_block_link">
        <!-- visualization -->
        <visual>
            <!-- appearance -->
            <geometry>
                <box size="2 2 0.1" />
                <!-- Import external models -->
            </geometry>
            <origin rpy="0 0 0" xyz="0 0 0" />
            <!-- Linkage offset -->
            <!-- texture of material -->
            <material name="">
                <color rgba="0.8 0.8 0.8 1" />
                <!-- colour -->
            </material>
        </visual>
        <!-- Collision matrix -->
        <collision>
            <!-- appearance -->
            <geometry>
                <box size="2 2 0.1" />
            </geometry>
            <origin rpy="0 0 0" xyz="0 0 0" />
        </collision>
        <inertial>
            <mass value="1000" />
            <inertia ixx="334.1666666666667" ixy="0" ixz="0" iyy="666.6666666666666" iyz="0" izz="334.1666666666667" />
            <origin xyz="0 0 0" rpy="0 0 0" />
        </inertial>
    </link>
    <gazebo reference="fixed_block_link">
        <material>Gazebo/Grey</material>
        <plugin name="gazebo_ros_control" filename="libgazebo_ros_control.so">
            <robotNamespace>/</robotNamespace>
        </plugin>
    </gazebo>
    <gazebo>
        <plugin filename="libgazebo_ros_control.so" name="gazebo_ros_control">
            <robotNamespace>/</robotNamespace>
        </plugin>
    </gazebo>
    <link name="base_link1">
        <visual>
            <geometry>
                <mesh filename="package://model/meshes/base_link.STL" />
            </geometry>
            <origin rpy="0 0 0" xyz="0 0 0" />
            <material name="">
                <color rgba="0.4 0.4 0.4 1" />
            </material>
        </visual>
        <collision>
            <geometry>
                <mesh filename="package://model/meshes/base_link.STL" />
            </geometry>
            <origin rpy="0 0 0" xyz="0 0 0" />
        </collision>
        <inertial>
            <origin rpy="0 0 0" xyz="2.0867E-05 0.0024582 0.036484" />
            <mass value="0.15198" />
            <inertia ixx="0.00015886" ixy="-9.6174E-09" ixz="-1.3936E-07" iyy="0.00016928" iyz="-2.6347E-06" izz="0.00018505" />
        </inertial>
    </link>
    <joint name="base_link1_joint" type="fixed">
        <parent link="fixed_block_link" />
        <child link="base_link1" />
        <origin rpy="0 0 0" xyz="-0.5 0.5 0.05" />
    </joint>
    <gazebo reference="base_link1">
        <material>Gazebo/Grey</material>
    </gazebo>
    <link name="link1_1">
        <visual>
            <origin rpy="0 0 0" xyz="0 0 0" />
            <geometry>
                <mesh filename="package://model/meshes/Link1.STL" />
            </geometry>
            <material name="">
                <color rgba="0.4 0.4 0.4 1" />
            </material>
        </visual>
        <collision>
            <origin rpy="0 0 0" xyz="0 0 0" />
            <geometry>
                <mesh filename="package://model/meshes/Link1.STL" />
            </geometry>
        </collision>
        <inertial>
            <origin rpy="0 0 0" xyz="-0.000150569497344115 0.0104209638029447 0.0714669079248176" />
            <mass value="0.051454447593722" />
            <inertia ixx="4.28042027375435E-05" ixy="2.49335097665302E-08" ixz="9.07504091461259E-08" iyy="5.10332068673238E-05" iyz="-7.62078054651406E-06" izz="2.92976443195118E-05" />
        </inertial>
    </link>
    <joint name="link1_1_joint" type="revolute">
        <origin rpy="0 0 0" xyz="0 0 0.10219" />
        <parent link="base_link1" />
        <child link="link1_1" />
        <axis xyz="0 0 1" />
        <limit effort="15" lower="-3.14159265358979" upper="3.14159265358979" velocity="1.047197551" />
        <dynamics friction="0.1" />
        <damping damping="0.1" friction="0.1" />
    </joint>
    <gazebo reference="link1_1">
        <material>Gazebo/Grey</material>
    </gazebo>
    <link name="link1_2">
        <visual>
            <geometry>
                <mesh filename="package://model/meshes/Link2.STL" />
            </geometry>
            <origin rpy="0 0 0" xyz="0 0 0" />
            <material name="">
                <color rgba="0.4 0.4 0.4 1" />
            </material>
        </visual>
        <collision>
            <origin rpy="0 0 0" xyz="0 0 0" />
            <geometry>
                <mesh filename="package://model/meshes/Link2.STL" />
            </geometry>
        </collision>
        <inertial>
            <origin rpy="0 0 0" xyz="0.0013842 0.12526 -0.00060222" />
            <mass value="0.072677" />
            <inertia ixx="0.00022891" ixy="-1.8752E-06" ixz="5.9632E-07" iyy="5.567E-05" iyz="5.7498E-05" izz="0.00022514" />
        </inertial>
    </link>
    <joint name="link1_2_joint" type="revolute">
        <origin rpy="1.5708 0 0" xyz="-0.00013672 0.0015197 0.083559" />
        <parent link="link1_1" />
        <child link="link1_2" />
        <axis xyz="0 0 -1" />
        <limit effort="15" lower="-3.14159265358979" upper="3.14159265358979" velocity="1.047197551" />
        <dynamics friction="0.1" />
        <damping damping="0.1" friction="0.1" />
    </joint>
    <gazebo reference="link1_2">
        <material>Gazebo/Grey</material>
    </gazebo>
    <link name="link1_3">
        <inertial>
            <origin rpy="0 0 0" xyz="-4.4371E-05 0.052245 0.010403" />
            <mass value="0.037334" />
            <inertia ixx="3.0107E-05" ixy="-8.289E-09" ixz="3.0001E-10" iyy="2.1927E-05" iyz="5.725E-06" izz="3.0817E-05" />
        </inertial>
        <visual>
            <origin rpy="0 0 0" xyz="0 0 0" />
            <geometry>
                <mesh filename="package://model/meshes/Link3.STL" />
            </geometry>
            <material name="">
                <color rgba="0.4 0.4 0.4 1" />
            </material>
        </visual>
        <collision>
            <origin rpy="0 0 0" xyz="0 0 0" />
            <geometry>
                <mesh filename="package://model/meshes/Link3.STL" />
            </geometry>
        </collision>
    </link>
    <joint name="link1_3_joint" type="revolute">
        <origin rpy="0 0 0" xyz="0.0020288 0.17799 0.00098033" />
        <parent link="link1_2" />
        <child link="link1_3" />
        <axis xyz="0 0 -1" />
        <limit effort="15" lower="-3.14159265358979" upper="3.14159265358979" velocity="1.047197551" />
        <dynamics friction="0.1" />
        <damping damping="0.1" friction="0.1" />
    </joint>
    <gazebo reference="link1_3">
        <material>Gazebo/Grey</material>
    </gazebo>
    <link name="link1_4">
        <visual>
            <origin rpy="0 0 0" xyz="0 0 0" />
            <geometry>
                <mesh filename="package://model/meshes/Link4.STL" />
            </geometry>
            <material name="">
                <color rgba="0.4 0.4 0.4 1" />
            </material>
        </visual>
        <collision>
            <origin rpy="0 0 0" xyz="0 0 0" />
            <geometry>
                <mesh filename="package://model/meshes/Link4.STL" />
            </geometry>
        </collision>
        <inertial>
            <origin rpy="0 0 0" xyz="-5.2487E-05 0.0067451 0.061697" />
            <mass value="0.033849" />
            <inertia ixx="2.198E-05" ixy="-2.6958E-10" ixz="-2.1485E-09" iyy="2.4927E-05" iyz="-4.3969E-06" izz="1.4623E-05" />
        </inertial>
    </link>
    <joint name="link1_4_joint" type="revolute">
        <parent link="link1_3" />
        <child link="link1_4" />
        <origin rpy="-1.5708 0 0" xyz="0 0.0834 0.0025888" />
        <axis xyz="0 0 -1" />
        <limit effort="4" lower="-3.14159265358979" upper="3.14159265358979" velocity="1.047197551" />
        <dynamics friction="0.1" />
        <damping damping="0.1" friction="0.1" />
    </joint>
    <gazebo reference="link1_4">
        <material>Gazebo/Grey</material>
    </gazebo>
    <link name="link1_5">
        <visual>
            <origin rpy="0 0 0" xyz="0 0 0" />
            <geometry>
                <mesh filename="package://model/meshes/Link5.STL" />
            </geometry>
            <material name="">
                <color rgba="0.4 0.4 0.4 1" />
            </material>
        </visual>
        <collision>
            <origin rpy="0 0 0" xyz="0 0 0" />
            <geometry>
                <mesh filename="package://model/meshes/Link5.STL" />
            </geometry>
        </collision>
        <inertial>
            <origin rpy="0 0 0" xyz="1.1017E-06 0.054029 0.0075175" />
            <mass value="0.02592" />
            <inertia ixx="2.8761E-05" ixy="2.8281E-09" ixz="-9.6456E-10" iyy="1.2811E-05" iyz="5.6623E-06" izz="2.8429E-05" />
        </inertial>
    </link>
    <joint name="link1_5_joint" type="revolute">
        <origin rpy="1.5708 0 0" xyz="0 6.188E-05 0.07454" />
        <parent link="link1_4" />
        <child link="link1_5" />
        <axis xyz="0 0 -1" />
        <limit effort="4" lower="-3.14159265358979" upper="3.14159265358979" velocity="1.047197551" />
        <dynamics damping="0.1" friction="0.1" />
    </joint>
    <gazebo reference="link1_5">
        <material>Gazebo/Grey</material>
    </gazebo>
    <link name="link1_6">
        <inertial>
            <origin rpy="0 0 0" xyz="-0.0010295 0.0096747 0.03161" />
            <mass value="0.10313" />
            <inertia ixx="8.4264E-05" ixy="2.616E-07" ixz="4.258E-06" iyy="9.4566E-05" iyz="-1.5572E-05" izz="6.3131E-05" />
        </inertial>
        <visual>
            <origin rpy="0 0 0" xyz="0 0 0" />
            <geometry>
                <mesh filename="package://model/meshes/Link6.STL" />
            </geometry>
            <material name="">
                <color rgba="0.4 0.4 0.4 1" />
            </material>
        </visual>
        <collision>
            <origin rpy="0 0 0" xyz="0 0 0" />
            <geometry>
                <mesh filename="package://model/meshes/Link6.STL" />
            </geometry>
        </collision>
    </link>
    <joint name="link1_6_joint" type="revolute">
        <origin rpy="1.5708 1.5499 3.1391" xyz="0.00025051 0.10055 0" />
        <parent link="link1_5" />
        <child link="link1_6" />
        <axis xyz="0 0 -1" />
        <limit effort="5" lower="-3.14" upper="3.14" velocity="1" />
        <dynamics damping="0.1" friction="0.1" />
    </joint>
    <gazebo reference="link1_6">
        <material>Gazebo/Grey</material>
    </gazebo>
    <link name="link1_7">
        <inertial>
            <origin rpy="0 0 0" xyz="-0.00799 0.039452 -0.014945" />
            <mass value="0.039237" />
            <inertia ixx="3.966E-05" ixy="8.1331E-07" ixz="-4.2778E-11" iyy="2.4954E-05" iyz="-4.2913E-10" izz="2.0954E-05" />
        </inertial>
        <visual>
            <origin rpy="0 0 0" xyz="0 0 0" />
            <geometry>
                <mesh filename="package://model/meshes/Link7.STL" />
            </geometry>
            <material name="">
                <color rgba="0.4 0.4 0.4 1" />
            </material>
        </visual>
        <collision>
            <origin rpy="0 0 0" xyz="0 0 0" />
            <geometry>
                <mesh filename="package://model/meshes/Link7.STL" />
            </geometry>
        </collision>
    </link>
    <joint name="link1_7_joint" type="revolute">
        <origin rpy="1.5708 0.0073902 1.5408" xyz="0.015818 -0.00047499 0.036" />
        <parent link="link1_6" />
        <child link="link1_7" />
        <axis xyz="0 0 -1" />
        <limit effort="5" lower="-1.5" upper="0" velocity="1" />
    </joint>
    <gazebo reference="link1_7">
        <material>Gazebo/Grey</material>
    </gazebo>
    <transmission name="link1_1_joint_trans">
        <type>transmission_interface/SimpleTransmission</type>
        <joint name="link1_1_joint">
            <hardwareInterface>hardware_interface/EffortJointInterface</hardwareInterface>
        </joint>
        <actuator name="foo_motor">
            <mechanicalReduction>1</mechanicalReduction>
            <hardwareInterface>hardware_interface/EffortJointInterface</hardwareInterface>
        </actuator>
    </transmission>
    <transmission name="link1_2_joint_trans">
        <type>transmission_interface/SimpleTransmission</type>
        <joint name="link1_2_joint">
            <hardwareInterface>hardware_interface/EffortJointInterface</hardwareInterface>
        </joint>
        <actuator name="foo_motor">
            <mechanicalReduction>1</mechanicalReduction>
            <hardwareInterface>hardware_interface/EffortJointInterface</hardwareInterface>
        </actuator>
    </transmission>
    <transmission name="link1_3_joint_trans">
        <type>transmission_interface/SimpleTransmission</type>
        <joint name="link1_3_joint">
            <hardwareInterface>hardware_interface/EffortJointInterface</hardwareInterface>
        </joint>
        <actuator name="foo_motor">
            <mechanicalReduction>1</mechanicalReduction>
            <hardwareInterface>hardware_interface/EffortJointInterface</hardwareInterface>
        </actuator>
    </transmission>
    <transmission name="link1_4_joint_trans">
        <type>transmission_interface/SimpleTransmission</type>
        <joint name="link1_4_joint">
            <hardwareInterface>hardware_interface/EffortJointInterface</hardwareInterface>
        </joint>
        <actuator name="foo_motor">
            <mechanicalReduction>1</mechanicalReduction>
            <hardwareInterface>hardware_interface/EffortJointInterface</hardwareInterface>
        </actuator>
    </transmission>
    <transmission name="link1_5_joint_trans">
        <type>transmission_interface/SimpleTransmission</type>
        <joint name="link1_5_joint">
            <hardwareInterface>hardware_interface/EffortJointInterface</hardwareInterface>
        </joint>
        <actuator name="foo_motor">
            <mechanicalReduction>1</mechanicalReduction>
            <hardwareInterface>hardware_interface/EffortJointInterface</hardwareInterface>
        </actuator>
    </transmission>
    <transmission name="link1_6_joint_trans">
        <type>transmission_interface/SimpleTransmission</type>
        <joint name="link1_6_joint">
            <hardwareInterface>hardware_interface/EffortJointInterface</hardwareInterface>
        </joint>
        <actuator name="foo_motor">
            <mechanicalReduction>1</mechanicalReduction>
            <hardwareInterface>hardware_interface/EffortJointInterface</hardwareInterface>
        </actuator>
    </transmission>
    <transmission name="link1_7_joint_trans">
        <type>transmission_interface/SimpleTransmission</type>
        <joint name="link1_7_joint">
            <hardwareInterface>hardware_interface/EffortJointInterface</hardwareInterface>
        </joint>
        <actuator name="foo_motor">
            <mechanicalReduction>1</mechanicalReduction>
            <hardwareInterface>hardware_interface/EffortJointInterface</hardwareInterface>
        </actuator>
    </transmission>
    <!-- <xacro:Robot_arm_create arm_number="2" pos_l="-${fixed_block_length/2-0.5}" pos_w="-${fixed_block_wide/2-0.5}" /> -->
</robot>

