<robot name="arm_dyn" xmlns:xacro="http://wiki.ros.org/xacro">

    <xacro:macro name="Link1_create" params="name joint_parent">
        <link name="${name}">
            <visual>
                <origin xyz="0 0 0" rpy="0 0 0" />
                <geometry>
                    <mesh filename="package://model/meshes/Link1.STL" />
                </geometry>
                <material name="">
                    <color rgba="0.4 0.4 0.4 1" />
                </material>
            </visual>

            <collision>
                <origin xyz="0 0 0" rpy="0 0 0" />
                <geometry>
                    <mesh filename="package://model/meshes/Link1.STL" />
                </geometry>
            </collision>

            <inertial>
                <origin xyz="-0.000150569497344115 0.0104209638029447 0.0714669079248176" rpy="0 0 0" />
                <mass value="0.051454447593722" />
                <inertia ixx="4.28042027375435E-05" ixy="2.49335097665302E-08" ixz="9.07504091461259E-08" iyy="5.10332068673238E-05" iyz="-7.62078054651406E-06" izz="2.92976443195118E-05" />
            </inertial>
        </link>

        <joint name="${name}_joint" type="revolute">
            <origin xyz="0 0 0.10219" rpy="0 0 0" />
            <parent link="${joint_parent}" />
            <child link="${name}" />
            <axis xyz="0 0 1" />
            <limit lower="${joint_lower}" upper="${joint_upper}" effort="${M5210_effort}" velocity="${M5210_velocity}" />
            <dynamics friction="0.1"/>
            <damping friction="0.1" damping="0.1" />
        </joint>

        <gazebo reference="${name}">
            <material>Gazebo/Grey</material>
        </gazebo>
    </xacro:macro>

</robot>