<robot name="arm_dyn" xmlns:xacro="http://wiki.ros.org/xacro">
  <xacro:macro name="Link4_create" params="name joint_parent">
      <!-- 连杆4 -->
    <link name="${name}">
      <visual>
        <origin xyz="0 0 0" rpy="0 0 0" />
        <geometry>
          <mesh filename="package://model/meshes/Link4.STL" />
        </geometry>
        <material name="">
          <color rgba="0.4 0.4 0.4 1" />
        </material>
      </visual>

      <collision>
        <origin xyz="0 0 0" rpy="0 0 0" />
        <geometry>
          <mesh filename="package://model/meshes/Link4.STL" />
        </geometry>
      </collision>

      <inertial>
        <origin xyz="-5.2487E-05 0.0067451 0.061697" rpy="0 0 0" />
        <mass value="0.033849" />
        <inertia ixx="2.198E-05" ixy="-2.6958E-10" ixz="-2.1485E-09" iyy="2.4927E-05" iyz="-4.3969E-06" izz="1.4623E-05" />
      </inertial>
    </link>

    <joint name="${name}_joint" type="revolute">
      <parent link="${joint_parent}" />
      <child link="${name}" />
      <origin xyz="0 0.0834 0.0025888" rpy="-1.5708 0 0" />
      <axis xyz="0 0 -1" />
      <limit lower="${joint_lower}" upper="${joint_upper}" effort="${M4010_effort}" velocity="${M4010_velocity}" />
      <dynamics friction="0.1"/>
      <damping friction="0.1"  damping="0.1" />
    </joint>

    <gazebo reference="${name}">
      <material>Gazebo/Grey</material>
    </gazebo>
  </xacro:macro>

</robot>